Traceback (most recent call last):
  File "/usr/share/miniconda/lib/python3.9/site-packages/jupyter_cache/executors/utils.py", line 51, in single_nb_execution
    executenb(
  File "/usr/share/miniconda/lib/python3.9/site-packages/nbclient/client.py", line 1204, in execute
    return NotebookClient(nb=nb, resources=resources, km=km, **kwargs).execute()
  File "/usr/share/miniconda/lib/python3.9/site-packages/nbclient/util.py", line 84, in wrapped
    return just_run(coro(*args, **kwargs))
  File "/usr/share/miniconda/lib/python3.9/site-packages/nbclient/util.py", line 62, in just_run
    return loop.run_until_complete(coro)
  File "/usr/share/miniconda/lib/python3.9/asyncio/base_events.py", line 647, in run_until_complete
    return future.result()
  File "/usr/share/miniconda/lib/python3.9/site-packages/nbclient/client.py", line 663, in async_execute
    await self.async_execute_cell(
  File "/usr/share/miniconda/lib/python3.9/site-packages/nbclient/client.py", line 965, in async_execute_cell
    await self._check_raise_for_error(cell, cell_index, exec_reply)
  File "/usr/share/miniconda/lib/python3.9/site-packages/nbclient/client.py", line 862, in _check_raise_for_error
    raise CellExecutionError.from_cell_and_msg(cell, exec_reply_content)
nbclient.exceptions.CellExecutionError: An error occurred while executing the following cell:
------------------
base_data_url = 'https://data.science.stsci.edu/redirect/JWST/jwst-data_analysis_tools/soss-transit-spectroscopy'
transit_model_path = 'hp1_model.txt'
transit_fits_results_path = 'transit_spectra_results.pkl'

if not os.path.exists('calibrated_data_hatp1_transit.fits'):
    file_path = download_file(base_data_url + '/data/calibrated_data_hatp1_transit.fits')
    os.rename(file_path, 'calibrated_data_hatp1_transit.fits')
    
if not os.path.exists(transit_model_path):
    file_path = download_file(base_data_url + '/data/hp1_tspec.dat')
    os.rename(file_path, transit_model_path)
    
if not os.path.exists(transit_fits_results_path):
    file_path = download_file(base_data_url + '/data/transit_spectra_results.pkl')
    os.rename(file_path, transit_fits_results_path)
------------------

[0;31m---------------------------------------------------------------------------[0m
[0;31mContentTooShortError[0m                      Traceback (most recent call last)
Input [0;32mIn [2][0m, in [0;36m<cell line: 5>[0;34m()[0m
[1;32m      3[0m transit_fits_results_path [38;5;241m=[39m [38;5;124m'[39m[38;5;124mtransit_spectra_results.pkl[39m[38;5;124m'[39m
[1;32m      5[0m [38;5;28;01mif[39;00m [38;5;129;01mnot[39;00m os[38;5;241m.[39mpath[38;5;241m.[39mexists([38;5;124m'[39m[38;5;124mcalibrated_data_hatp1_transit.fits[39m[38;5;124m'[39m):
[0;32m----> 6[0m     file_path [38;5;241m=[39m [43mdownload_file[49m[43m([49m[43mbase_data_url[49m[43m [49m[38;5;241;43m+[39;49m[43m [49m[38;5;124;43m'[39;49m[38;5;124;43m/data/calibrated_data_hatp1_transit.fits[39;49m[38;5;124;43m'[39;49m[43m)[49m
[1;32m      7[0m     os[38;5;241m.[39mrename(file_path, [38;5;124m'[39m[38;5;124mcalibrated_data_hatp1_transit.fits[39m[38;5;124m'[39m)
[1;32m      9[0m [38;5;28;01mif[39;00m [38;5;129;01mnot[39;00m os[38;5;241m.[39mpath[38;5;241m.[39mexists(transit_model_path):

File [0;32m/usr/share/miniconda/lib/python3.9/site-packages/astropy/utils/data.py:1393[0m, in [0;36mdownload_file[0;34m(remote_url, cache, show_progress, timeout, sources, pkgname, http_headers, ssl_context, allow_insecure)[0m
[1;32m   1388[0m     [38;5;28;01mraise[39;00m [38;5;167;01mKeyError[39;00m(
[1;32m   1389[0m         [38;5;124mf[39m[38;5;124m"[39m[38;5;124mNo sources listed and file [39m[38;5;132;01m{[39;00mremote_url[38;5;132;01m}[39;00m[38;5;124m not in cache! [39m[38;5;124m"[39m
[1;32m   1390[0m         [38;5;124mf[39m[38;5;124m"[39m[38;5;124mPlease include primary URL in sources if you want it to be [39m[38;5;124m"[39m
[1;32m   1391[0m         [38;5;124mf[39m[38;5;124m"[39m[38;5;124mincluded as a valid source.[39m[38;5;124m"[39m)
[1;32m   1392[0m [38;5;28;01melif[39;00m [38;5;28mlen[39m(sources) [38;5;241m==[39m [38;5;241m1[39m:
[0;32m-> 1393[0m     [38;5;28;01mraise[39;00m errors[sources[[38;5;241m0[39m]]
[1;32m   1394[0m [38;5;28;01melse[39;00m:
[1;32m   1395[0m     [38;5;28;01mraise[39;00m urllib[38;5;241m.[39merror[38;5;241m.[39mURLError(
[1;32m   1396[0m         [38;5;124mf[39m[38;5;124m"[39m[38;5;124mUnable to open any source! Exceptions were [39m[38;5;132;01m{[39;00merrors[38;5;132;01m}[39;00m[38;5;124m"[39m) \
[1;32m   1397[0m         [38;5;28;01mfrom[39;00m [38;5;21;01merrors[39;00m[sources[[38;5;241m0[39m]]

File [0;32m/usr/share/miniconda/lib/python3.9/site-packages/astropy/utils/data.py:1363[0m, in [0;36mdownload_file[0;34m(remote_url, cache, show_progress, timeout, sources, pkgname, http_headers, ssl_context, allow_insecure)[0m
[1;32m   1361[0m [38;5;28;01mfor[39;00m source_url [38;5;129;01min[39;00m sources:
[1;32m   1362[0m     [38;5;28;01mtry[39;00m:
[0;32m-> 1363[0m         f_name [38;5;241m=[39m [43m_download_file_from_source[49m[43m([49m
[1;32m   1364[0m [43m                [49m[43msource_url[49m[43m,[49m
[1;32m   1365[0m [43m                [49m[43mtimeout[49m[38;5;241;43m=[39;49m[43mtimeout[49m[43m,[49m
[1;32m   1366[0m [43m                [49m[43mshow_progress[49m[38;5;241;43m=[39;49m[43mshow_progress[49m[43m,[49m
[1;32m   1367[0m [43m                [49m[43mcache[49m[38;5;241;43m=[39;49m[43mcache[49m[43m,[49m
[1;32m   1368[0m [43m                [49m[43mremote_url[49m[38;5;241;43m=[39;49m[43mremote_url[49m[43m,[49m
[1;32m   1369[0m [43m                [49m[43mpkgname[49m[38;5;241;43m=[39;49m[43mpkgname[49m[43m,[49m
[1;32m   1370[0m [43m                [49m[43mhttp_headers[49m[38;5;241;43m=[39;49m[43mhttp_headers[49m[43m,[49m
[1;32m   1371[0m [43m                [49m[43mssl_context[49m[38;5;241;43m=[39;49m[43mssl_context[49m[43m,[49m
[1;32m   1372[0m [43m                [49m[43mallow_insecure[49m[38;5;241;43m=[39;49m[43mallow_insecure[49m[43m)[49m
[1;32m   1373[0m         [38;5;66;03m# Success![39;00m
[1;32m   1374[0m         [38;5;28;01mbreak[39;00m

File [0;32m/usr/share/miniconda/lib/python3.9/site-packages/astropy/utils/data.py:1208[0m, in [0;36m_download_file_from_source[0;34m(source_url, show_progress, timeout, remote_url, cache, pkgname, http_headers, ftp_tls, ssl_context, allow_insecure)[0m
[1;32m   1203[0m             [38;5;28;01mraise[39;00m urllib[38;5;241m.[39merror[38;5;241m.[39mURLError(
[1;32m   1204[0m                 [38;5;124mf[39m[38;5;124m"[39m[38;5;124mFile was supposed to be [39m[38;5;132;01m{[39;00msize[38;5;132;01m}[39;00m[38;5;124m bytes but [39m[38;5;124m"[39m
[1;32m   1205[0m                 [38;5;124mf[39m[38;5;124m"[39m[38;5;124mserver provides more, at least [39m[38;5;132;01m{[39;00mbytes_read[38;5;132;01m}[39;00m[38;5;124m [39m[38;5;124m"[39m
[1;32m   1206[0m                 [38;5;124mf[39m[38;5;124m"[39m[38;5;124mbytes. Download failed.[39m[38;5;124m"[39m)
[1;32m   1207[0m     [38;5;28;01mif[39;00m size [38;5;129;01mis[39;00m [38;5;129;01mnot[39;00m [38;5;28;01mNone[39;00m [38;5;129;01mand[39;00m bytes_read [38;5;241m<[39m size:
[0;32m-> 1208[0m         [38;5;28;01mraise[39;00m urllib[38;5;241m.[39merror[38;5;241m.[39mContentTooShortError(
[1;32m   1209[0m             [38;5;124mf[39m[38;5;124m"[39m[38;5;124mFile was supposed to be [39m[38;5;132;01m{[39;00msize[38;5;132;01m}[39;00m[38;5;124m bytes but we [39m[38;5;124m"[39m
[1;32m   1210[0m             [38;5;124mf[39m[38;5;124m"[39m[38;5;124monly got [39m[38;5;132;01m{[39;00mbytes_read[38;5;132;01m}[39;00m[38;5;124m bytes. Download failed.[39m[38;5;124m"[39m,
[1;32m   1211[0m             content[38;5;241m=[39m[38;5;28;01mNone[39;00m)
[1;32m   1212[0m [38;5;28;01mexcept[39;00m [38;5;167;01mBaseException[39;00m:
[1;32m   1213[0m     [38;5;28;01mif[39;00m os[38;5;241m.[39mpath[38;5;241m.[39mexists(f[38;5;241m.[39mname):

[0;31mContentTooShortError[0m: <urlopen error File was supposed to be 15124867200 bytes but we only got 484675584 bytes. Download failed.>
ContentTooShortError: <urlopen error File was supposed to be 15124867200 bytes but we only got 484675584 bytes. Download failed.>

